2022-03-30 11:38:11,009 INFO    MainThread:291666 [wandb_setup.py:_flush():75] Loading settings from /home/ubuntu/.config/wandb/settings
2022-03-30 11:38:11,009 INFO    MainThread:291666 [wandb_setup.py:_flush():75] Loading settings from /home/ubuntu/project/ml/wandb/settings
2022-03-30 11:38:11,009 INFO    MainThread:291666 [wandb_setup.py:_flush():75] Loading settings from environment variables: {}
2022-03-30 11:38:11,009 INFO    MainThread:291666 [wandb_setup.py:_flush():75] Inferring run settings from compute environment: {'program': '<python with no main file>'}
2022-03-30 11:38:11,009 INFO    MainThread:291666 [wandb_setup.py:_flush():75] Applying login settings: {'api_key': '***REDACTED***'}
2022-03-30 11:38:11,009 INFO    MainThread:291666 [wandb_init.py:_log_setup():405] Logging user logs to /home/ubuntu/project/ml/wandb/run-20220330_113811-2zxjvh67/logs/debug.log
2022-03-30 11:38:11,009 INFO    MainThread:291666 [wandb_init.py:_log_setup():406] Logging internal logs to /home/ubuntu/project/ml/wandb/run-20220330_113811-2zxjvh67/logs/debug-internal.log
2022-03-30 11:38:11,010 INFO    MainThread:291666 [wandb_init.py:_jupyter_setup():355] configuring jupyter hooks <wandb.sdk.wandb_init._WandbInit object at 0x7f11df44abe0>
2022-03-30 11:38:11,010 INFO    MainThread:291666 [wandb_init.py:init():439] calling init triggers
2022-03-30 11:38:11,010 INFO    MainThread:291666 [wandb_init.py:init():442] wandb.init called with sweep_config: {}
config: {}
2022-03-30 11:38:11,010 INFO    MainThread:291666 [wandb_init.py:init():492] starting backend
2022-03-30 11:38:11,010 INFO    MainThread:291666 [backend.py:_multiprocessing_setup():99] multiprocessing start_methods=fork,spawn,forkserver, using: spawn
2022-03-30 11:38:11,013 INFO    MainThread:291666 [backend.py:ensure_launched():219] starting backend process...
2022-03-30 11:38:11,019 INFO    MainThread:291666 [backend.py:ensure_launched():224] started backend process with pid: 291774
2022-03-30 11:38:11,023 INFO    MainThread:291666 [wandb_init.py:init():501] backend started and connected
2022-03-30 11:38:11,033 INFO    MainThread:291666 [wandb_run.py:_label_probe_notebook():947] probe notebook
2022-03-30 11:38:11,033 INFO    MainThread:291666 [wandb_run.py:_label_probe_notebook():957] Unable to probe notebook: 'NoneType' object has no attribute 'get'
2022-03-30 11:38:11,033 INFO    MainThread:291666 [wandb_init.py:init():565] updated telemetry
2022-03-30 11:38:11,056 INFO    MainThread:291666 [wandb_init.py:init():596] communicating run to backend with 30 second timeout
2022-03-30 11:38:12,752 INFO    MainThread:291666 [wandb_run.py:_on_init():1759] communicating current version
2022-03-30 11:38:12,856 INFO    MainThread:291666 [wandb_run.py:_on_init():1763] got version response 
2022-03-30 11:38:12,856 INFO    MainThread:291666 [wandb_init.py:init():625] starting run threads in backend
2022-03-30 11:38:12,955 INFO    MainThread:291666 [wandb_run.py:_console_start():1733] atexit reg
2022-03-30 11:38:12,955 INFO    MainThread:291666 [wandb_run.py:_redirect():1606] redirect: SettingsConsole.WRAP
2022-03-30 11:38:12,956 INFO    MainThread:291666 [wandb_run.py:_redirect():1643] Wrapping output streams.
2022-03-30 11:38:12,957 INFO    MainThread:291666 [wandb_run.py:_redirect():1667] Redirects installed.
2022-03-30 11:38:12,957 INFO    MainThread:291666 [wandb_init.py:init():664] run started, returning control to user process
2022-03-30 11:39:43,097 ERROR   MainThread:291666 [retry.py:__call__():126] Retry attempt failed:
Traceback (most recent call last):
  File "/usr/lib/python3/dist-packages/urllib3/connection.py", line 159, in _new_conn
    conn = connection.create_connection(
  File "/usr/lib/python3/dist-packages/urllib3/util/connection.py", line 61, in create_connection
    for res in socket.getaddrinfo(host, port, family, socket.SOCK_STREAM):
  File "/usr/lib/python3.8/socket.py", line 918, in getaddrinfo
    for res in _socket.getaddrinfo(host, port, family, type, proto, flags):
socket.gaierror: [Errno -3] Temporary failure in name resolution

During handling of the above exception, another exception occurred:

Traceback (most recent call last):
  File "/usr/lib/python3/dist-packages/urllib3/connectionpool.py", line 665, in urlopen
    httplib_response = self._make_request(
  File "/usr/lib/python3/dist-packages/urllib3/connectionpool.py", line 376, in _make_request
    self._validate_conn(conn)
  File "/usr/lib/python3/dist-packages/urllib3/connectionpool.py", line 996, in _validate_conn
    conn.connect()
  File "/usr/lib/python3/dist-packages/urllib3/connection.py", line 314, in connect
    conn = self._new_conn()
  File "/usr/lib/python3/dist-packages/urllib3/connection.py", line 171, in _new_conn
    raise NewConnectionError(
urllib3.exceptions.NewConnectionError: <urllib3.connection.VerifiedHTTPSConnection object at 0x7f11dbdc4130>: Failed to establish a new connection: [Errno -3] Temporary failure in name resolution

During handling of the above exception, another exception occurred:

Traceback (most recent call last):
  File "/usr/lib/python3/dist-packages/requests/adapters.py", line 439, in send
    resp = conn.urlopen(
  File "/usr/lib/python3/dist-packages/urllib3/connectionpool.py", line 719, in urlopen
    retries = retries.increment(
  File "/usr/lib/python3/dist-packages/urllib3/util/retry.py", line 436, in increment
    raise MaxRetryError(_pool, url, error or ResponseError(cause))
urllib3.exceptions.MaxRetryError: HTTPSConnectionPool(host='api.wandb.ai', port=443): Max retries exceeded with url: /graphql (Caused by NewConnectionError('<urllib3.connection.VerifiedHTTPSConnection object at 0x7f11dbdc4130>: Failed to establish a new connection: [Errno -3] Temporary failure in name resolution'))

During handling of the above exception, another exception occurred:

Traceback (most recent call last):
  File "/home/ubuntu/.local/lib/python3.8/site-packages/wandb/sdk/lib/retry.py", line 102, in __call__
    result = self._call_fn(*args, **kwargs)
  File "/home/ubuntu/.local/lib/python3.8/site-packages/wandb/sdk/internal/internal_api.py", line 140, in execute
    return self.client.execute(*args, **kwargs)
  File "/home/ubuntu/.local/lib/python3.8/site-packages/wandb/vendor/gql-0.2.0/wandb_gql/client.py", line 52, in execute
    result = self._get_result(document, *args, **kwargs)
  File "/home/ubuntu/.local/lib/python3.8/site-packages/wandb/vendor/gql-0.2.0/wandb_gql/client.py", line 60, in _get_result
    return self.transport.execute(document, *args, **kwargs)
  File "/home/ubuntu/.local/lib/python3.8/site-packages/wandb/vendor/gql-0.2.0/wandb_gql/transport/requests.py", line 38, in execute
    request = requests.post(self.url, **post_args)
  File "/usr/lib/python3/dist-packages/requests/api.py", line 116, in post
    return request('post', url, data=data, json=json, **kwargs)
  File "/usr/lib/python3/dist-packages/requests/api.py", line 60, in request
    return session.request(method=method, url=url, **kwargs)
  File "/usr/lib/python3/dist-packages/requests/sessions.py", line 533, in request
    resp = self.send(prep, **send_kwargs)
  File "/usr/lib/python3/dist-packages/requests/sessions.py", line 646, in send
    r = adapter.send(request, **kwargs)
  File "/usr/lib/python3/dist-packages/requests/adapters.py", line 516, in send
    raise ConnectionError(e, request=request)
requests.exceptions.ConnectionError: HTTPSConnectionPool(host='api.wandb.ai', port=443): Max retries exceeded with url: /graphql (Caused by NewConnectionError('<urllib3.connection.VerifiedHTTPSConnection object at 0x7f11dbdc4130>: Failed to establish a new connection: [Errno -3] Temporary failure in name resolution'))
2022-03-30 11:39:47,621 INFO    MainThread:291666 [wandb_run.py:finish():1539] finishing run sanderele1/beans-tabular-University-of-Stavanger/2zxjvh67
2022-03-30 11:39:47,622 INFO    MainThread:291666 [jupyter.py:save_history():429] not saving jupyter history
2022-03-30 11:39:47,622 INFO    MainThread:291666 [jupyter.py:save_ipynb():374] not saving jupyter notebook
2022-03-30 11:39:47,622 INFO    MainThread:291666 [wandb_init.py:_jupyter_teardown():337] cleaning up jupyter logic
2022-03-30 11:39:47,622 INFO    MainThread:291666 [wandb_run.py:_atexit_cleanup():1702] got exitcode: 0
2022-03-30 11:39:47,627 INFO    MainThread:291666 [wandb_run.py:_restore():1674] restore
2022-03-30 11:39:53,099 INFO    MainThread:291666 [wandb_run.py:_on_finish():1831] got exit ret: file_counts {
  wandb_count: 1
  media_count: 2
  artifact_count: 2
}
pusher_stats {
  uploaded_bytes: 6468013
  total_bytes: 6468013
}

2022-03-30 11:39:53,453 INFO    MainThread:291666 [wandb_run.py:_on_finish():1831] got exit ret: file_counts {
  wandb_count: 1
  media_count: 2
  artifact_count: 2
}
pusher_stats {
  uploaded_bytes: 6468013
  total_bytes: 6468013
}

2022-03-30 11:39:53,849 INFO    MainThread:291666 [wandb_run.py:_on_finish():1831] got exit ret: file_counts {
  wandb_count: 5
  media_count: 2
  artifact_count: 2
}
pusher_stats {
  uploaded_bytes: 6468013
  total_bytes: 6473554
}

2022-03-30 11:39:53,951 INFO    MainThread:291666 [wandb_run.py:_on_finish():1831] got exit ret: file_counts {
  wandb_count: 5
  media_count: 2
  artifact_count: 2
}
pusher_stats {
  uploaded_bytes: 6468013
  total_bytes: 6473554
}

2022-03-30 11:39:54,053 INFO    MainThread:291666 [wandb_run.py:_on_finish():1831] got exit ret: file_counts {
  wandb_count: 5
  media_count: 2
  artifact_count: 2
}
pusher_stats {
  uploaded_bytes: 6468013
  total_bytes: 6473554
}

2022-03-30 11:39:54,155 INFO    MainThread:291666 [wandb_run.py:_on_finish():1831] got exit ret: file_counts {
  wandb_count: 5
  media_count: 2
  artifact_count: 2
}
pusher_stats {
  uploaded_bytes: 6468013
  total_bytes: 6473554
}

2022-03-30 11:39:54,257 INFO    MainThread:291666 [wandb_run.py:_on_finish():1831] got exit ret: file_counts {
  wandb_count: 5
  media_count: 2
  artifact_count: 2
}
pusher_stats {
  uploaded_bytes: 6473554
  total_bytes: 6473554
}

2022-03-30 11:39:54,359 INFO    MainThread:291666 [wandb_run.py:_on_finish():1831] got exit ret: file_counts {
  wandb_count: 5
  media_count: 2
  artifact_count: 2
}
pusher_stats {
  uploaded_bytes: 6473554
  total_bytes: 6473554
}

2022-03-30 11:39:54,461 INFO    MainThread:291666 [wandb_run.py:_on_finish():1831] got exit ret: file_counts {
  wandb_count: 5
  media_count: 2
  artifact_count: 2
}
pusher_stats {
  uploaded_bytes: 6473554
  total_bytes: 6473554
}

2022-03-30 11:39:54,563 INFO    MainThread:291666 [wandb_run.py:_on_finish():1831] got exit ret: file_counts {
  wandb_count: 5
  media_count: 2
  artifact_count: 2
}
pusher_stats {
  uploaded_bytes: 6473554
  total_bytes: 6473554
}

2022-03-30 11:39:54,665 INFO    MainThread:291666 [wandb_run.py:_on_finish():1831] got exit ret: file_counts {
  wandb_count: 5
  media_count: 2
  artifact_count: 2
}
pusher_stats {
  uploaded_bytes: 6473554
  total_bytes: 6473554
}

2022-03-30 11:39:54,767 INFO    MainThread:291666 [wandb_run.py:_on_finish():1831] got exit ret: file_counts {
  wandb_count: 5
  media_count: 2
  artifact_count: 2
}
pusher_stats {
  uploaded_bytes: 6473554
  total_bytes: 6473554
}

2022-03-30 11:39:54,869 INFO    MainThread:291666 [wandb_run.py:_on_finish():1831] got exit ret: file_counts {
  wandb_count: 5
  media_count: 2
  artifact_count: 2
}
pusher_stats {
  uploaded_bytes: 6473554
  total_bytes: 6473554
}

2022-03-30 11:39:54,971 INFO    MainThread:291666 [wandb_run.py:_on_finish():1831] got exit ret: file_counts {
  wandb_count: 5
  media_count: 2
  artifact_count: 2
}
pusher_stats {
  uploaded_bytes: 6473554
  total_bytes: 6473554
}

2022-03-30 11:39:55,073 INFO    MainThread:291666 [wandb_run.py:_on_finish():1831] got exit ret: file_counts {
  wandb_count: 5
  media_count: 2
  artifact_count: 2
}
pusher_stats {
  uploaded_bytes: 6473554
  total_bytes: 6473554
}

2022-03-30 11:39:55,688 INFO    MainThread:291666 [wandb_run.py:_on_finish():1831] got exit ret: file_counts {
  wandb_count: 5
  media_count: 2
  artifact_count: 2
}
pusher_stats {
  uploaded_bytes: 6473554
  total_bytes: 6473554
}

2022-03-30 11:39:55,992 INFO    MainThread:291666 [wandb_run.py:_on_finish():1831] got exit ret: done: true
exit_result {
}
file_counts {
  wandb_count: 5
  media_count: 2
  artifact_count: 2
}
pusher_stats {
  uploaded_bytes: 6473554
  total_bytes: 6473554
}
local_info {
}

2022-03-30 11:39:57,181 INFO    MainThread:291666 [wandb_run.py:_footer_history_summary_info():2865] rendering history
2022-03-30 11:39:57,181 INFO    MainThread:291666 [wandb_run.py:_footer_history_summary_info():2894] rendering summary
2022-03-30 11:39:57,185 INFO    MainThread:291666 [wandb_run.py:_footer_sync_info():2822] logging synced files
